<?xml version="1.0" encoding="UTF-8"?>
<!-- Generated by org.testng.reporters.JUnitReportReporter -->
<testsuite hostname="LAPTOP-Q1P4S741" failures="2" tests="15" name="com.testcases.CustomerTests" time="14.327" errors="0" timestamp="2022-06-28T17:46:20 CEST" skipped="0">
  <testcase classname="com.testcases.CustomerTests" name="createCustomerWithValidKey" time="0.913"/>
  <system-out/>
  <testcase classname="com.testcases.CustomerTests" name="createCustomerWithValidKey" time="3.452"/>
  <system-out/>
  <testcase classname="com.testcases.CustomerTests" name="createCustomerWithValidKey" time="0.822"/>
  <system-out/>
  <testcase classname="com.testcases.CustomerTests" name="createCustomerWithInvalidKey" time="0.375"/>
  <system-out/>
  <testcase classname="com.testcases.CustomerTests" name="listAllCustomers" time="0.878"/>
  <system-out/>
  <testcase classname="com.testcases.CustomerTests" name="searchExistingTwoCustomers" time="0.739"/>
  <system-out/>
  <testcase classname="com.testcases.CustomerTests" name="searchCustomersWithValidQueryParameter" time="0.693"/>
  <system-out/>
  <testcase classname="com.testcases.CustomerTests" name="createCustomerWithInvalidPhoneNumber" time="0.672">
    <failure message="This fail is caused by API defect! expected [400] but found [200]" type="java.lang.AssertionError">
      <![CDATA[java.lang.AssertionError: This fail is caused by API defect! expected [400] but found [200]
at org.testng.Assert.fail(Assert.java:110)
at org.testng.Assert.failNotEquals(Assert.java:1413)
at org.testng.Assert.assertEqualsImpl(Assert.java:149)
at org.testng.Assert.assertEquals(Assert.java:131)
at org.testng.Assert.assertEquals(Assert.java:1240)
at com.testcases.CustomerTests.createCustomerWithInvalidPhoneNumber(CustomerTests.java:77)
at java.base/jdk.internal.reflect.NativeMethodAccessorImpl.invoke0(Native Method)
at java.base/jdk.internal.reflect.NativeMethodAccessorImpl.invoke(NativeMethodAccessorImpl.java:78)
at java.base/jdk.internal.reflect.DelegatingMethodAccessorImpl.invoke(DelegatingMethodAccessorImpl.java:43)
at java.base/java.lang.reflect.Method.invoke(Method.java:567)
at org.testng.internal.invokers.MethodInvocationHelper.invokeMethod(MethodInvocationHelper.java:135)
at org.testng.internal.invokers.TestInvoker.invokeMethod(TestInvoker.java:673)
at org.testng.internal.invokers.TestInvoker.invokeTestMethod(TestInvoker.java:220)
at org.testng.internal.invokers.MethodRunner.runInSequence(MethodRunner.java:50)
at org.testng.internal.invokers.TestInvoker$MethodInvocationAgent.invoke(TestInvoker.java:945)
at org.testng.internal.invokers.TestInvoker.invokeTestMethods(TestInvoker.java:193)
at org.testng.internal.invokers.TestMethodWorker.invokeTestMethods(TestMethodWorker.java:146)
at org.testng.internal.invokers.TestMethodWorker.run(TestMethodWorker.java:128)
at java.base/java.util.ArrayList.forEach(ArrayList.java:1511)
at org.testng.TestRunner.privateRun(TestRunner.java:808)
at org.testng.TestRunner.run(TestRunner.java:603)
at org.testng.SuiteRunner.runTest(SuiteRunner.java:429)
at org.testng.SuiteRunner.runSequentially(SuiteRunner.java:423)
at org.testng.SuiteRunner.privateRun(SuiteRunner.java:383)
at org.testng.SuiteRunner.run(SuiteRunner.java:326)
at org.testng.SuiteRunnerWorker.runSuite(SuiteRunnerWorker.java:52)
at org.testng.SuiteRunnerWorker.run(SuiteRunnerWorker.java:95)
at org.testng.TestNG.runSuitesSequentially(TestNG.java:1249)
at org.testng.TestNG.runSuitesLocally(TestNG.java:1169)
at org.testng.TestNG.runSuites(TestNG.java:1092)
at org.testng.TestNG.run(TestNG.java:1060)
at org.testng.remote.AbstractRemoteTestNG.run(AbstractRemoteTestNG.java:115)
at org.testng.remote.RemoteTestNG.initAndRun(RemoteTestNG.java:251)
at org.testng.remote.RemoteTestNG.main(RemoteTestNG.java:77)
]]>
    </failure>
  </testcase> <!-- createCustomerWithInvalidPhoneNumber -->
  <system-out/>
  <testcase classname="com.testcases.CustomerTests" name="createCustomerWithInvalidEmail" time="0.581">
    <failure message="This fail is caused by API defect! expected [400] but found [200]" type="java.lang.AssertionError">
      <![CDATA[java.lang.AssertionError: This fail is caused by API defect! expected [400] but found [200]
at org.testng.Assert.fail(Assert.java:110)
at org.testng.Assert.failNotEquals(Assert.java:1413)
at org.testng.Assert.assertEqualsImpl(Assert.java:149)
at org.testng.Assert.assertEquals(Assert.java:131)
at org.testng.Assert.assertEquals(Assert.java:1240)
at com.testcases.CustomerTests.createCustomerWithInvalidEmail(CustomerTests.java:85)
at java.base/jdk.internal.reflect.NativeMethodAccessorImpl.invoke0(Native Method)
at java.base/jdk.internal.reflect.NativeMethodAccessorImpl.invoke(NativeMethodAccessorImpl.java:78)
at java.base/jdk.internal.reflect.DelegatingMethodAccessorImpl.invoke(DelegatingMethodAccessorImpl.java:43)
at java.base/java.lang.reflect.Method.invoke(Method.java:567)
at org.testng.internal.invokers.MethodInvocationHelper.invokeMethod(MethodInvocationHelper.java:135)
at org.testng.internal.invokers.TestInvoker.invokeMethod(TestInvoker.java:673)
at org.testng.internal.invokers.TestInvoker.invokeTestMethod(TestInvoker.java:220)
at org.testng.internal.invokers.MethodRunner.runInSequence(MethodRunner.java:50)
at org.testng.internal.invokers.TestInvoker$MethodInvocationAgent.invoke(TestInvoker.java:945)
at org.testng.internal.invokers.TestInvoker.invokeTestMethods(TestInvoker.java:193)
at org.testng.internal.invokers.TestMethodWorker.invokeTestMethods(TestMethodWorker.java:146)
at org.testng.internal.invokers.TestMethodWorker.run(TestMethodWorker.java:128)
at java.base/java.util.ArrayList.forEach(ArrayList.java:1511)
at org.testng.TestRunner.privateRun(TestRunner.java:808)
at org.testng.TestRunner.run(TestRunner.java:603)
at org.testng.SuiteRunner.runTest(SuiteRunner.java:429)
at org.testng.SuiteRunner.runSequentially(SuiteRunner.java:423)
at org.testng.SuiteRunner.privateRun(SuiteRunner.java:383)
at org.testng.SuiteRunner.run(SuiteRunner.java:326)
at org.testng.SuiteRunnerWorker.runSuite(SuiteRunnerWorker.java:52)
at org.testng.SuiteRunnerWorker.run(SuiteRunnerWorker.java:95)
at org.testng.TestNG.runSuitesSequentially(TestNG.java:1249)
at org.testng.TestNG.runSuitesLocally(TestNG.java:1169)
at org.testng.TestNG.runSuites(TestNG.java:1092)
at org.testng.TestNG.run(TestNG.java:1060)
at org.testng.remote.AbstractRemoteTestNG.run(AbstractRemoteTestNG.java:115)
at org.testng.remote.RemoteTestNG.initAndRun(RemoteTestNG.java:251)
at org.testng.remote.RemoteTestNG.main(RemoteTestNG.java:77)
]]>
    </failure>
  </testcase> <!-- createCustomerWithInvalidEmail -->
  <system-out/>
  <testcase classname="com.testcases.CustomerTests" name="getCustomersWithSpecifiedEmailAddress" time="0.681"/>
  <system-out/>
  <testcase classname="com.testcases.CustomerTests" name="searchWithoutQueryParameter" time="0.630"/>
  <system-out/>
  <testcase classname="com.testcases.CustomerTests" name="createCustomerWithInvalidBalance" time="0.630"/>
  <system-out/>
  <testcase classname="com.testcases.CustomerTests" name="updateCustomer" time="1.849"/>
  <system-out/>
  <testcase classname="com.testcases.CustomerTests" name="deleteCustomer" time="0.754"/>
  <system-out/>
  <testcase classname="com.testcases.CustomerTests" name="RetrieveCustomer" time="0.658"/>
  <system-out/>
</testsuite> <!-- com.testcases.CustomerTests -->
